<mujoco>
    <!-- simple, two-joint "robot arm" -->
    <compiler angle="degree"/>
    <default>
        <joint limited="true" range="-90 90" damping="0.1" axis="0 1 0" type="hinge"/>
        <geom type="capsule" size="0.02" rgba="1 1 1 1"/>
    </default>
    <worldbody>
        <geom name="base" fromto="0 0 -0.1 0 0 0"/>
        <body name="proximal">
            <joint name="proximal"/>
            <geom name="proximal" fromto="0 0 0 0 0 0.1" size="0.015"/>
            <body name="distal" pos="0 0 0.1">
                <joint name="distal"/>
                <geom name="distal" fromto="0 0 0 0 0 0.1" size="0.01"/>
            </body>
        </body>
    </worldbody>
    <actuator>
        <motor name="proximal" joint="proximal"/>
        <motor name="distal" joint="distal"/>
    </actuator>
</mujoco>